Traceback (most recent call last):
  File "/home/thahn1230/anaconda3/envs/llamassp/lib/python3.8/site-packages/huggingface_hub/utils/_http.py", line 406, in hf_raise_for_status
    response.raise_for_status()
  File "/home/thahn1230/anaconda3/envs/llamassp/lib/python3.8/site-packages/requests/models.py", line 1024, in raise_for_status
    raise HTTPError(http_error_msg, response=self)
requests.exceptions.HTTPError: 404 Client Error: Not Found for url: https://huggingface.co/datasets/Salesforce/wikitext/resolve/b08601e04326c79dfdd32d625aee71d232d685c3/wikitext.py

The above exception was the direct cause of the following exception:

Traceback (most recent call last):
  File "/home/thahn1230/anaconda3/envs/llamassp/lib/python3.8/site-packages/datasets/load.py", line 1645, in dataset_module_factory
    dataset_script_path = api.hf_hub_download(
  File "/home/thahn1230/anaconda3/envs/llamassp/lib/python3.8/site-packages/huggingface_hub/utils/_validators.py", line 114, in _inner_fn
    return fn(*args, **kwargs)
  File "/home/thahn1230/anaconda3/envs/llamassp/lib/python3.8/site-packages/huggingface_hub/hf_api.py", line 5645, in hf_hub_download
    return hf_hub_download(
  File "/home/thahn1230/anaconda3/envs/llamassp/lib/python3.8/site-packages/huggingface_hub/utils/_validators.py", line 114, in _inner_fn
    return fn(*args, **kwargs)
  File "/home/thahn1230/anaconda3/envs/llamassp/lib/python3.8/site-packages/huggingface_hub/file_download.py", line 862, in hf_hub_download
    return _hf_hub_download_to_cache_dir(
  File "/home/thahn1230/anaconda3/envs/llamassp/lib/python3.8/site-packages/huggingface_hub/file_download.py", line 925, in _hf_hub_download_to_cache_dir
    (url_to_download, etag, commit_hash, expected_size, head_call_error) = _get_metadata_or_catch_error(
  File "/home/thahn1230/anaconda3/envs/llamassp/lib/python3.8/site-packages/huggingface_hub/file_download.py", line 1376, in _get_metadata_or_catch_error
    metadata = get_hf_file_metadata(
  File "/home/thahn1230/anaconda3/envs/llamassp/lib/python3.8/site-packages/huggingface_hub/utils/_validators.py", line 114, in _inner_fn
    return fn(*args, **kwargs)
  File "/home/thahn1230/anaconda3/envs/llamassp/lib/python3.8/site-packages/huggingface_hub/file_download.py", line 1296, in get_hf_file_metadata
    r = _request_wrapper(
  File "/home/thahn1230/anaconda3/envs/llamassp/lib/python3.8/site-packages/huggingface_hub/file_download.py", line 296, in _request_wrapper
    return _request_wrapper(method=method, url=next_url, follow_relative_redirects=True, **params)
  File "/home/thahn1230/anaconda3/envs/llamassp/lib/python3.8/site-packages/huggingface_hub/file_download.py", line 277, in _request_wrapper
    response = _request_wrapper(
  File "/home/thahn1230/anaconda3/envs/llamassp/lib/python3.8/site-packages/huggingface_hub/file_download.py", line 301, in _request_wrapper
    hf_raise_for_status(response)
  File "/home/thahn1230/anaconda3/envs/llamassp/lib/python3.8/site-packages/huggingface_hub/utils/_http.py", line 417, in hf_raise_for_status
    raise _format(EntryNotFoundError, message, response) from e
huggingface_hub.errors.EntryNotFoundError: 404 Client Error. (Request ID: Root=1-67f7cedb-21236ddb225e718d42c64636;1cfa8891-ccd7-4c82-a9af-eb8d7ab305c0)

Entry Not Found for url: https://huggingface.co/datasets/Salesforce/wikitext/resolve/b08601e04326c79dfdd32d625aee71d232d685c3/wikitext.py.

During handling of the above exception, another exception occurred:

Traceback (most recent call last):
  File "advanced_rl_optimization.py", line 20, in <module>
    from llamassp import create_model, tokenizer, models_params, MAX_NEW_TOKENS
  File "/home/thahn1230/llama-ssp-quant/llamassp.py", line 95, in <module>
    dataset = load_dataset("wikitext", "wikitext-2-raw-v1", split="test")
  File "/home/thahn1230/anaconda3/envs/llamassp/lib/python3.8/site-packages/datasets/load.py", line 2132, in load_dataset
    builder_instance = load_dataset_builder(
  File "/home/thahn1230/anaconda3/envs/llamassp/lib/python3.8/site-packages/datasets/load.py", line 1853, in load_dataset_builder
    dataset_module = dataset_module_factory(
  File "/home/thahn1230/anaconda3/envs/llamassp/lib/python3.8/site-packages/datasets/load.py", line 1686, in dataset_module_factory
    return HubDatasetModuleFactoryWithoutScript(
  File "/home/thahn1230/anaconda3/envs/llamassp/lib/python3.8/site-packages/datasets/load.py", line 1024, in get_module
    standalone_yaml_path = cached_path(
  File "/home/thahn1230/anaconda3/envs/llamassp/lib/python3.8/site-packages/datasets/utils/file_utils.py", line 178, in cached_path
    resolved_path = huggingface_hub.HfFileSystem(
  File "/home/thahn1230/anaconda3/envs/llamassp/lib/python3.8/site-packages/huggingface_hub/hf_file_system.py", line 175, in resolve_path
    repo_and_revision_exist, err = self._repo_and_revision_exist(repo_type, repo_id, revision)
  File "/home/thahn1230/anaconda3/envs/llamassp/lib/python3.8/site-packages/huggingface_hub/hf_file_system.py", line 121, in _repo_and_revision_exist
    self._api.repo_info(
  File "/home/thahn1230/anaconda3/envs/llamassp/lib/python3.8/site-packages/huggingface_hub/utils/_validators.py", line 114, in _inner_fn
    return fn(*args, **kwargs)
  File "/home/thahn1230/anaconda3/envs/llamassp/lib/python3.8/site-packages/huggingface_hub/hf_api.py", line 2756, in repo_info
    return method(
  File "/home/thahn1230/anaconda3/envs/llamassp/lib/python3.8/site-packages/huggingface_hub/utils/_validators.py", line 114, in _inner_fn
    return fn(*args, **kwargs)
  File "/home/thahn1230/anaconda3/envs/llamassp/lib/python3.8/site-packages/huggingface_hub/hf_api.py", line 2613, in dataset_info
    r = get_session().get(path, headers=headers, timeout=timeout, params=params)
  File "/home/thahn1230/anaconda3/envs/llamassp/lib/python3.8/site-packages/requests/sessions.py", line 602, in get
    return self.request("GET", url, **kwargs)
  File "/home/thahn1230/anaconda3/envs/llamassp/lib/python3.8/site-packages/requests/sessions.py", line 589, in request
    resp = self.send(prep, **send_kwargs)
  File "/home/thahn1230/anaconda3/envs/llamassp/lib/python3.8/site-packages/requests/sessions.py", line 724, in send
    history = [resp for resp in gen]
  File "/home/thahn1230/anaconda3/envs/llamassp/lib/python3.8/site-packages/requests/sessions.py", line 724, in <listcomp>
    history = [resp for resp in gen]
  File "/home/thahn1230/anaconda3/envs/llamassp/lib/python3.8/site-packages/requests/sessions.py", line 265, in resolve_redirects
    resp = self.send(
  File "/home/thahn1230/anaconda3/envs/llamassp/lib/python3.8/site-packages/requests/sessions.py", line 703, in send
    r = adapter.send(request, **kwargs)
  File "/home/thahn1230/anaconda3/envs/llamassp/lib/python3.8/site-packages/huggingface_hub/utils/_http.py", line 93, in send
    return super().send(request, *args, **kwargs)
  File "/home/thahn1230/anaconda3/envs/llamassp/lib/python3.8/site-packages/requests/adapters.py", line 667, in send
    resp = conn.urlopen(
  File "/home/thahn1230/anaconda3/envs/llamassp/lib/python3.8/site-packages/urllib3/connectionpool.py", line 789, in urlopen
    response = self._make_request(
  File "/home/thahn1230/anaconda3/envs/llamassp/lib/python3.8/site-packages/urllib3/connectionpool.py", line 536, in _make_request
    response = conn.getresponse()
  File "/home/thahn1230/anaconda3/envs/llamassp/lib/python3.8/site-packages/urllib3/connection.py", line 507, in getresponse
    httplib_response = super().getresponse()
  File "/home/thahn1230/anaconda3/envs/llamassp/lib/python3.8/http/client.py", line 1348, in getresponse
    response.begin()
  File "/home/thahn1230/anaconda3/envs/llamassp/lib/python3.8/http/client.py", line 316, in begin
    version, status, reason = self._read_status()
  File "/home/thahn1230/anaconda3/envs/llamassp/lib/python3.8/http/client.py", line 277, in _read_status
    line = str(self.fp.readline(_MAXLINE + 1), "iso-8859-1")
  File "/home/thahn1230/anaconda3/envs/llamassp/lib/python3.8/socket.py", line 681, in readinto
    return self._sock.recv_into(b)
  File "/home/thahn1230/anaconda3/envs/llamassp/lib/python3.8/ssl.py", line 1274, in recv_into
    return self.read(nbytes, buffer)
  File "/home/thahn1230/anaconda3/envs/llamassp/lib/python3.8/ssl.py", line 1132, in read
    return self._sslobj.read(len, buffer)
KeyboardInterrupt
